Workbook

Sheet Area prompt
A1: Id | B1: Floor | C1: Image id | D1: Image Type | E1: True x | F1: True y | G1: Predicted x | H1: Predicted y | I1: Euclidean error | J1: Reasoning | K1: Floor & Image id | L1: Column 12 | M1: Unique floor & image | N1: Max EE | O1: Min EE | P1: Diff between max and min | R1: No of changed groups | S1: Percentage of changed groups
A2: T1.1 | B2: Floor 5 | C2: 1.1 | D2: Wide | E2: 39 | F2: 15 | G2: 37 | H2: 17 | I2: 2.828 | J2: The query image most likely shows the pantry/kitchen area labeled 505 PENRTY. Visible kitchenette fixtures, sloped ceiling, and a doorway into an office match this room. The camera appears to be standing inside the pantry near its open side, looking toward the kitchenette wall and the door to the adjacent office, so the best estimate is near the center-lower part of room 505. | K2: =B2&"|"&C2 -> Floor 5|1.1 | M2: {=UNIQUE(K2:K109)} -> Floor 5|1.1 | N2: =IFERROR(__xludf.DUMMYFUNCTION("MIN(FILTER($I$2:$I109,$K$2:$K109=M2))"),2.828) -> 2.828 | O2: =IFERROR(__xludf.DUMMYFUNCTION("MAX(FILTER($I$2:$I109,$K$2:$K109=M2))"),2.828) -> 2.828 | P2: =O2-N2 -> 0 | R2: =COUNTIF(P2:P109,">0") -> 35 | S2: =COUNTIF(P2:P109,">0")/COUNTA(M2:M109) -> 0.97222222
A3: T1.2 | B3: Floor 5 | C3: 1.1 | D3: Wide | E3: 39 | F3: 15 | G3: 37 | H3: 17 | I3: 2.828 | J3: The query image most likely shows the pantry/kitchen area labeled 505 PENRTY: it has a kitchenette with fridge, sink, microwaves, and sloped ceiling/window geometry matching the outer roof edge. The camera appears to be inside that pantry, near its open side toward the large office area, facing the kitchen counter and doorway, so the best estimate is a point slightly inside room 505 near its center-left edge. | K3: =B3&"|"&C3 -> Floor 5|1.1 | M3: Floor 5|1.2 | N3: =IFERROR(__xludf.DUMMYFUNCTION("MIN(FILTER($I$2:$I109,$K$2:$K109=M3))"),2.828) -> 2.828 | O3: =IFERROR(__xludf.DUMMYFUNCTION("MAX(FILTER($I$2:$I109,$K$2:$K109=M3))"),5.657) -> 5.657 | P3: =O3-N3 -> 2.829 | R3: =COUNTIF(P2:P109,">1") -> 27 | S3: =COUNTIF(P2:P109,">1")/COUNTA(M2:M109) -> 0.75
A4: T1.3 | B4: Floor 5 | C4: 1.1 | D4: Wide | E4: 39 | F4: 15 | G4: 37 | H4: 17 | I4: 2.828 | J4: The query image most likely shows the kitchenette/pantry area, which matches room 505 ‘PENTRY’ on the floorplan: visible fridge, microwaves, sink, coffee area, and sloped exterior wall/window. The camera appears to be standing inside the pantry near its open side, looking toward the kitchen cabinets with the doorway to the adjacent office/open area visible ahead. | K4: =B4&"|"&C4 -> Floor 5|1.1 | M4: Floor 5|1_pano | N4: =IFERROR(__xludf.DUMMYFUNCTION("MIN(FILTER($I$2:$I109,$K$2:$K109=M4))"),2.828) -> 2.828 | O4: =IFERROR(__xludf.DUMMYFUNCTION("MAX(FILTER($I$2:$I109,$K$2:$K109=M4))"),3.162) -> 3.162 | P4: =O4-N4 -> 0.334 | R4: =COUNTIF(P2:P109,">3") -> 12 | S4: =COUNTIF(P2:P109,">3")/COUNTA(M2:M109) -> 0.33333333
A5: T1.4 | B5: Floor 5 | C5: 1.2 | D5: Wide | E5: 39 | F5: 15 | G5: 35 | H5: 19 | I5: 5.657 | J5: The photo most likely shows the boundary between room 505 PENTRY and the open office 504 KONTORSLANDSKAP: there is a kitchenette/fridge on the right, tiled flooring in the foreground, carpeted open office with desks and windows on the left, and an exit door ahead. The best camera position is just inside the pentry/open-office transition area, looking toward the windows and the door. | K5: =B5&"|"&C5 -> Floor 5|1.2 | M5: Floor 5|2.1 | N5: =IFERROR(__xludf.DUMMYFUNCTION("MIN(FILTER($I$2:$I109,$K$2:$K109=M5))"),0.0) -> 0 | O5: =IFERROR(__xludf.DUMMYFUNCTION("MAX(FILTER($I$2:$I109,$K$2:$K109=M5))"),1.0) -> 1 | P5: =O5-N5 -> 1 | R5: =COUNTIF(P2:P109,">5") -> 8 | S5: =COUNTIF(P2:P109,">5")/COUNTA(M2:M109) -> 0.22222222
A6: T1.5 | B6: Floor 5 | C6: 1.2 | D6: Wide | E6: 39 | F6: 15 | G6: 37 | H6: 17 | I6: 2.828 | J6: The photo most likely shows the pantry/open office edge around room 505 PENRTY opening into 504 KONTORSLANDSKAP. Visible clues are the kitchenette refrigerator on the right, tiled pantry floor transitioning to carpeted open office on the left, and large exterior windows in the office area. The camera appears to stand in the pantry/open office threshold, just inside the tiled area facing toward the open office and windows. | K6: =B6&"|"&C6 -> Floor 5|1.2 | M6: Floor 5|2.2 | N6: =IFERROR(__xludf.DUMMYFUNCTION("MIN(FILTER($I$2:$I109,$K$2:$K109=M6))"),4.472) -> 4.472 | O6: =IFERROR(__xludf.DUMMYFUNCTION("MAX(FILTER($I$2:$I109,$K$2:$K109=M6))"),12.166) -> 12.166 | P6: =O6-N6 -> 7.694 | R6: =COUNTIF(P3:P109,">10") -> 2 | S6: =COUNTIF(P3:P109,">10")/COUNTA(M3:M109) -> 0.057142857
A7: T1.6 | B7: Floor 5 | C7: 1.2 | D7: Wide | E7: 39 | F7: 15 | G7: 36 | H7: 17 | I7: 3.606 | J7: The query shows the pantry/open-office threshold: tiled kitchenette floor on the right with a tall fridge, carpeted open office with desks and windows on the left, and a small passage/door ahead. This best matches the 505 PENTRY opening into 504 KONTORSLANDSKAP near the small internal passage, so the camera is placed just inside the pantry edge facing into the open office. | K7: =B7&"|"&C7 -> Floor 5|1.2 | M7: Floor 5|2.pano | N7: =IFERROR(__xludf.DUMMYFUNCTION("MIN(FILTER($I$2:$I109,$K$2:$K109=M7))"),0.0) -> 0 | O7: =IFERROR(__xludf.DUMMYFUNCTION("MAX(FILTER($I$2:$I109,$K$2:$K109=M7))"),1.0) -> 1 | P7: =O7-N7 -> 1
A8: T1.7 | B8: Floor 5 | C8: 1_pano | D8: Panorama | E8: 39 | F8: 15 | G8: 38 | H8: 18 | I8: 3.162 | J8: The query shows a pantry/kitchenette opening directly into a larger meeting/lounge area with a sloped exterior wall and a row of low windows. On the plan, this best matches room 505 PENRTY adjacent to 506 MÖTESRUM. The camera is most likely positioned in the pantry area near its opening toward the meeting room, looking across the kitchenette and windows. | K8: =B8&"|"&C8 -> Floor 5|1_pano | M8: Floor 5|3.1 | N8: =IFERROR(__xludf.DUMMYFUNCTION("MIN(FILTER($I$2:$I109,$K$2:$K109=M8))"),6.325) -> 6.325 | O8: =IFERROR(__xludf.DUMMYFUNCTION("MAX(FILTER($I$2:$I109,$K$2:$K109=M8))"),7.81) -> 7.81 | P8: =O8-N8 -> 1.485
A9: T1.8 | B9: Floor 5 | C9: 1_pano | D9: Panorama | E9: 39 | F9: 15 | G9: 37 | H9: 17 | I9: 2.828 | J9: The query shows a pantry/break area with kitchenette and a sloped facade wall with a row of low windows, opening directly toward an open office. This best matches room 505 PENTRY beside the large 504 office area and near the angled exterior wall. The point is placed inside 505 near its opening toward the office, where the camera could look across the kitchenette and toward the windows. | K9: =B9&"|"&C9 -> Floor 5|1_pano | M9: Floor 5|3.2 | N9: =IFERROR(__xludf.DUMMYFUNCTION("MIN(FILTER($I$2:$I109,$K$2:$K109=M9))"),9.22) -> 9.22 | O9: =IFERROR(__xludf.DUMMYFUNCTION("MAX(FILTER($I$2:$I109,$K$2:$K109=M9))"),12.207) -> 12.207 | P9: =O9-N9 -> 2.987
A10: T1.9 | B10: Floor 5 | C10: 1_pano | D10: Panorama | E10: 39 | F10: 15 | G10: 37 | H10: 17 | I10: 2.828 | J10: The query shows a pantry/break area with kitchenette, microwaves, fridge, dining tables, and a sloped wall with low windows. This best matches room 505 PENRTY adjacent to the open office 504. The camera is likely positioned inside the pantry near its middle-left side, looking toward the windowed outer wall and kitchenette. | K10: =B10&"|"&C10 -> Floor 5|1_pano | M10: Floor 5|3_pano | N10: =IFERROR(__xludf.DUMMYFUNCTION("MIN(FILTER($I$2:$I109,$K$2:$K109=M10))"),6.403) -> 6.403 | O10: =IFERROR(__xludf.DUMMYFUNCTION("MAX(FILTER($I$2:$I109,$K$2:$K109=M10))"),12.042) -> 12.042 | P10: =O10-N10 -> 5.639
A11: T1.10 | B11: Floor 5 | C11: 2.1 | D11: Wide | E11: 44 | F11: 16 | G11: 44 | H11: 16 | I11: 0 | J11: The photo shows a small office under a sloped roof with two exterior windows meeting at a corner, which best matches the corner office 507. The camera appears to be inside that room near the entrance/inner side, looking toward the angled exterior corner windows, so I placed the point slightly inside room 507 away from the window corner. | K11: =B11&"|"&C11 -> Floor 5|2.1 | M11: Floor 5|4.1 | N11: =IFERROR(__xludf.DUMMYFUNCTION("MIN(FILTER($I$2:$I109,$K$2:$K109=M11))"),8.485) -> 8.485 | O11: =IFERROR(__xludf.DUMMYFUNCTION("MAX(FILTER($I$2:$I109,$K$2:$K109=M11))"),10.0) -> 10 | P11: =O11-N11 -> 1.515
A12: T1.11 | B12: Floor 5 | C12: 2.1 | D12: Wide | E12: 44 | F12: 16 | G12: 44 | H12: 17 | I12: 1 | J12: The photo shows a very small perimeter office with a strongly sloped ceiling and two exterior windows meeting near a corner, which best matches the wedge-shaped top office 507 along the angled facade. The camera appears to be placed inside that room near its inner side, looking outward toward the two windows, so I place it slightly back from the facade within room 507. | K12: =B12&"|"&C12 -> Floor 5|2.1 | M12: Floor 5|4.2 | N12: =IFERROR(__xludf.DUMMYFUNCTION("MIN(FILTER($I$2:$I109,$K$2:$K109=M12))"),19.723) -> 19.723 | O12: =IFERROR(__xludf.DUMMYFUNCTION("MAX(FILTER($I$2:$I109,$K$2:$K109=M12))"),20.248) -> 20.248 | P12: =O12-N12 -> 0.525
A13: T1.12 | B13: Floor 5 | C13: 2.1 | D13: Wide | E13: 44 | F13: 16 | G13: 44 | H13: 17 | I13: 1 | J13: The photo shows a very small office under a sloped roof with two exterior windows meeting at a corner, which best matches the small corner office 507. The camera appears placed just inside the doorway looking toward the windowed corner, so the best estimate is in the interior of room 507 near its entrance side. | K13: =B13&"|"&C13 -> Floor 5|2.1 | M13: Floor 5|4.pano | N13: =IFERROR(__xludf.DUMMYFUNCTION("MIN(FILTER($I$2:$I109,$K$2:$K109=M13))"),12.649) -> 12.649 | O13: =IFERROR(__xludf.DUMMYFUNCTION("MAX(FILTER($I$2:$I109,$K$2:$K109=M13))"),18.385) -> 18.385 | P13: =O13-N13 -> 5.736
A14: T1.13 | B14: Floor 5 | C14: 2.2 | D14: Wide | E14: 44 | F14: 16 | G14: 42 | H14: 20 | I14: 4.472 | J14: The query appears to be taken inside a small office looking out through a doorway into the larger open office area with visible columns. On the plan, room 517 (KONTOR) best matches a small office directly connected to the open area 504, with the door opening toward the open office. The camera is likely positioned inside 517 near the back-right side of the room, facing outward through the doorway. | K14: =B14&"|"&C14 -> Floor 5|2.2 | M14: Floor 5|5.1 | N14: =IFERROR(__xludf.DUMMYFUNCTION("MIN(FILTER($I$2:$I109,$K$2:$K109=M14))"),20.616) -> 20.616 | O14: =IFERROR(__xludf.DUMMYFUNCTION("MAX(FILTER($I$2:$I109,$K$2:$K109=M14))"),21.26) -> 21.26 | P14: =O14-N14 -> 0.644
A15: T1.14 | B15: Floor 5 | C15: 2.2 | D15: Wide | E15: 44 | F15: 16 | G15: 42 | H15: 28 | I15: 12.166 | J15: The photo is most consistent with a small office room opening into the larger open office area 504 KONTORSLANDSKAP. The visible interior column and the doorway looking out toward a larger space fit best with room 517 KONTOR, which sits just below 504 and has a door into that open area. The point is placed inside 517 near its doorway, matching the camera looking outward into 504. | K15: =B15&"|"&C15 -> Floor 5|2.2 | M15: Floor 5|5.2 | N15: =IFERROR(__xludf.DUMMYFUNCTION("MIN(FILTER($I$2:$I109,$K$2:$K109=M15))"),1.0) -> 1 | O15: =IFERROR(__xludf.DUMMYFUNCTION("MAX(FILTER($I$2:$I109,$K$2:$K109=M15))"),3.0) -> 3 | P15: =O15-N15 -> 2
A16: T1.15 | B16: Floor 5 | C16: 2.2 | D16: Wide | E16: 44 | F16: 16 | G16: 43 | H16: 28 | I16: 12.042 | J16: The photo appears to be taken inside a small office with a structural column, looking out through a single door into the larger open office area with visible columns and furniture. On the floorplan, room 517 (KONTOR) best matches this setup: a small office opening directly into the open workspace 504 near the service core. The point is placed inside room 517, a bit back from the doorway, matching the camera position looking outward into 504. | K16: =B16&"|"&C16 -> Floor 5|2.2 | M16: Floor 5|5.pano | N16: =IFERROR(__xludf.DUMMYFUNCTION("MIN(FILTER($I$2:$I109,$K$2:$K109=M16))"),7.28) -> 7.28 | O16: =IFERROR(__xludf.DUMMYFUNCTION("MAX(FILTER($I$2:$I109,$K$2:$K109=M16))"),13.342) -> 13.342 | P16: =O16-N16 -> 6.062
A17: T1.16 | B17: Floor 5 | C17: 2.pano | D17: Panorama | E17: 44 | F17: 16 | G17: 44 | H17: 16 | I17: 0 | J17: The query shows a small office under a sloped roof with a row of exterior windows on one long side and a single door opening to the corridor. On the floorplan, the best match is office 507 at the upper-right edge: it has the angled exterior wall with windows and connects by one door to the internal circulation. The camera appears placed inside that office near the windowed side, looking back toward the door, so the best position is within room 507 slightly in from the exterior wall. | K17: =B17&"|"&C17 -> Floor 5|2.pano | M17: Floor 5|6.1 | N17: =IFERROR(__xludf.DUMMYFUNCTION("MIN(FILTER($I$2:$I109,$K$2:$K109=M17))"),5.0) -> 5 | O17: =IFERROR(__xludf.DUMMYFUNCTION("MAX(FILTER($I$2:$I109,$K$2:$K109=M17))"),5.657) -> 5.657 | P17: =O17-N17 -> 0.657
A18: T1.17 | B18: Floor 5 | C18: 2.pano | D18: Panorama | E18: 44 | F18: 16 | G18: 44 | H18: 16 | I18: 0 | J18: The query shows a small perimeter office with a sloped exterior wall/ceiling and a row of windows, looking back through the door into a corridor. On the floorplan, the best match is one of the upper-right offices along the angled facade, most likely room 507. The point is placed inside that office near the windowed outer wall, with the camera aimed back toward the door into the corridor. | K18: =B18&"|"&C18 -> Floor 5|2.pano | M18: Floor 5|6.2 | N18: =IFERROR(__xludf.DUMMYFUNCTION("MIN(FILTER($I$2:$I109,$K$2:$K109=M18))"),3.0) -> 3 | O18: =IFERROR(__xludf.DUMMYFUNCTION("MAX(FILTER($I$2:$I109,$K$2:$K109=M18))"),3.162) -> 3.162 | P18: =O18-N18 -> 0.162
A19: T1.18 | B19: Floor 5 | C19: 2.pano | D19: Panorama | E19: 44 | F19: 16 | G19: 44 | H19: 17 | I19: 1 | J19: The query shows a small perimeter office under a sloped roof with a long row of exterior windows on the right and a doorway opening into a corridor/passage. This best matches one of the angled offices along the northeast facade, most likely room 507. The point is placed inside 507 near the windowed outer wall, looking back toward the door into the passage/corridor. | K19: =B19&"|"&C19 -> Floor 5|2.pano | M19: Floor 5|6_pano | N19: =IFERROR(__xludf.DUMMYFUNCTION("MIN(FILTER($I$2:$I109,$K$2:$K109=M19))"),4.243) -> 4.243 | O19: =IFERROR(__xludf.DUMMYFUNCTION("MAX(FILTER($I$2:$I109,$K$2:$K109=M19))"),5.657) -> 5.657 | P19: =O19-N19 -> 1.414
A20: T1.19 | B20: Floor 5 | C20: 3.1 | D20: Wide | E20: 39 | F20: 22 | G20: 44 | H20: 16 | I20: 7.81 | J20: The query shows a small office with several desks directly against an exterior window wall and a faceted corner view. On the plan, the best match is room 507 KONTOR at the upper-right perimeter, which has this angled exterior facade and office scale. The camera is likely placed inside 507 a few meters back from the windows, near the inner side of the room facing outward. | K20: =B20&"|"&C20 -> Floor 5|3.1 | M20: Floor 3|1.1 | N20: =IFERROR(__xludf.DUMMYFUNCTION("MIN(FILTER($I$2:$I109,$K$2:$K109=M20))"),25.08) -> 25.08 | O20: =IFERROR(__xludf.DUMMYFUNCTION("MAX(FILTER($I$2:$I109,$K$2:$K109=M20))"),30.017) -> 30.017 | P20: =O20-N20 -> 4.937
A21: T1.20 | B21: Floor 5 | C21: 3.1 | D21: Wide | E21: 39 | F21: 22 | G21: 44 | H21: 17 | I21: 7.071 | J21: The query shows a small office with several desks directly along an exterior window wall. On the floorplan, the most likely match is one of the wedge-shaped perimeter offices on the right side rather than the large open office. The view and room size best fit room 507 KONTOR, with the camera placed near its interior side looking outward toward the angled facade windows. | K21: =B21&"|"&C21 -> Floor 5|3.1 | M21: Floor 3|1.2 | N21: =IFERROR(__xludf.DUMMYFUNCTION("MIN(FILTER($I$2:$I109,$K$2:$K109=M21))"),25.0) -> 25 | O21: =IFERROR(__xludf.DUMMYFUNCTION("MAX(FILTER($I$2:$I109,$K$2:$K109=M21))"),28.636) -> 28.636 | P21: =O21-N21 -> 3.636
A22: T1.21 | B22: Floor 5 | C22: 3.1 | D22: Wide | E22: 39 | F22: 22 | G22: 45 | H22: 20 | I22: 6.325 | J22: The query shows a small perimeter office with several desks and a faceted exterior window wall. On the floorplan, the best match is room 508 KONTOR along the angled east facade, which has broad exterior windows and office-sized proportions. The camera is most likely positioned inside 508 near its interior side, facing outward toward the windows. | K22: =B22&"|"&C22 -> Floor 5|3.1 | M22: Floor 3|1.pano | N22: =IFERROR(__xludf.DUMMYFUNCTION("MIN(FILTER($I$2:$I109,$K$2:$K109=M22))"),6.403) -> 6.403 | O22: =IFERROR(__xludf.DUMMYFUNCTION("MAX(FILTER($I$2:$I109,$K$2:$K109=M22))"),27.514) -> 27.514 | P22: =O22-N22 -> 21.111
A23: T1.22 | B23: Floor 5 | C23: 3.2 | D23: Wide | E23: 39 | F23: 22 | G23: 31 | H23: 17 | I23: 9.434 | J23: The query image most likely shows the large meeting room 506 (MÖTESRUM): it has a conference table and chairs by a long windowed wall, matching this room better than the smaller offices. The camera appears to be inside the room near its lower-left/central side, looking toward an internal partition/TV wall with the windows off to the right, so the best estimate is a point within room 506 slightly left of center. | K23: =B23&"|"&C23 -> Floor 5|3.2 | M23: Floor 3|2.1 | N23: =IFERROR(__xludf.DUMMYFUNCTION("MIN(FILTER($I$2:$I109,$K$2:$K109=M23))"),2.236) -> 2.236 | O23: =IFERROR(__xludf.DUMMYFUNCTION("MAX(FILTER($I$2:$I109,$K$2:$K109=M23))"),3.162) -> 3.162 | P23: =O23-N23 -> 0.926
A24: T1.23 | B24: Floor 5 | C24: 3.2 | D24: Wide | E24: 39 | F24: 22 | G24: 32 | H24: 24 | I24: 9.22 | J24: The query image most likely shows the meeting room 506 (MÖTESRUM): it has a conference table and chairs by a row of low windows along the exterior wall. The TV mounted on an angled interior partition matches the distinctive slanted wall inside room 506, so the camera is best placed inside 506 near the lower-right side of the room, looking toward that partition and the windows. | K24: =B24&"|"&C24 -> Floor 5|3.2 | M24: Floor 3|2.2 | N24: =IFERROR(__xludf.DUMMYFUNCTION("MIN(FILTER($I$2:$I109,$K$2:$K109=M24))"),2.236) -> 2.236 | O24: =IFERROR(__xludf.DUMMYFUNCTION("MAX(FILTER($I$2:$I109,$K$2:$K109=M24))"),5.0) -> 5 | P24: =O24-N24 -> 2.764
A25: T1.24 | B25: Floor 5 | C25: 3.2 | D25: Wide | E25: 39 | F25: 22 | G25: 32 | H25: 12 | I25: 12.207 | J25: The query shows a furnished meeting room/open collaboration area: conference table and chairs by a windowed facade, plus a TV mounted on a partition wall. On the floorplan, room 506 (MÖTESRUM) best matches this type of space and location near the angled exterior windows. The camera is likely positioned inside 506 near its lower-left/central side, looking toward an internal partition and the window side. | K25: =B25&"|"&C25 -> Floor 5|3.2 | M25: Floor 3|2_pano | N25: =IFERROR(__xludf.DUMMYFUNCTION("MIN(FILTER($I$2:$I109,$K$2:$K109=M25))"),2.236) -> 2.236 | O25: =IFERROR(__xludf.DUMMYFUNCTION("MAX(FILTER($I$2:$I109,$K$2:$K109=M25))"),3.606) -> 3.606 | P25: =O25-N25 -> 1.37
A26: T1.25 | B26: Floor 5 | C26: 3_pano | D26: Panorama | E26: 39 | F26: 22 | G26: 35 | H26: 17 | I26: 6.403 | J26: The query shows a conference/meeting room with a large oval table, exterior windows along one side, and glass-partitioned rooms/corridor on the opposite side. On the floorplan, room 506 (MÖTESRUM) best matches this layout: it is the main meeting room on the windowed upper facade, adjacent to the internal corridor and nearby glass-fronted office area. The camera is most likely placed inside 506 near its lower-central edge, looking across the table toward the interior side. | K26: =B26&"|"&C26 -> Floor 5|3_pano | M26: Floor 3|3.1 | N26: =IFERROR(__xludf.DUMMYFUNCTION("MIN(FILTER($I$2:$I109,$K$2:$K109=M26))"),2.236) -> 2.236 | O26: =IFERROR(__xludf.DUMMYFUNCTION("MAX(FILTER($I$2:$I109,$K$2:$K109=M26))"),5.0) -> 5 | P26: =O26-N26 -> 2.764
A27: T1.26 | B27: Floor 5 | C27: 3_pano | D27: Panorama | E27: 39 | F27: 22 | G27: 34 | H27: 12 | I27: 11.18 | J27: The query shows a meeting room/open office area with many windows along an exterior wall, a large conference table, and adjacent smaller glass-fronted offices. This best matches room 506 MÖTESRUM at the top center-right of the plan, looking toward the neighboring office rooms along the angled facade. The camera is most likely placed inside 506 near its lower-left/central side. | K27: =B27&"|"&C27 -> Floor 5|3_pano | M27: Floor 3|3.2 | N27: =IFERROR(__xludf.DUMMYFUNCTION("MIN(FILTER($I$2:$I109,$K$2:$K109=M27))"),3.162) -> 3.162 | O27: =IFERROR(__xludf.DUMMYFUNCTION("MAX(FILTER($I$2:$I109,$K$2:$K109=M27))"),5.385) -> 5.385 | P27: =O27-N27 -> 2.223
A28: T1.27 | B28: Floor 5 | C28: 3_pano | D28: Panorama | E28: 39 | F28: 22 | G28: 31 | H28: 13 | I28: 12.042 | J28: The query shows a large meeting room with a big conference table, exterior windows along one side, and glass-partitioned offices/corridor on the opposite side. This best matches room 506 MÖTESRUM at the top-center of the plan. The camera appears positioned inside that meeting room, slightly toward the window side and looking across toward the interior glass wall and doors. | K28: =B28&"|"&C28 -> Floor 5|3_pano | M28: Floor 3|3_pano | N28: =IFERROR(__xludf.DUMMYFUNCTION("MIN(FILTER($I$2:$I109,$K$2:$K109=M28))"),5.0) -> 5 | O28: =IFERROR(__xludf.DUMMYFUNCTION("MAX(FILTER($I$2:$I109,$K$2:$K109=M28))"),15.232) -> 15.232 | P28: =O28-N28 -> 10.232
A29: T1.31 | B29: Floor 5 | C29: 4.1 | D29: Wide | E29: 42 | F29: 29 | G29: 36 | H29: 23 | I29: 8.485 | J29: The query shows an open office area with perimeter windows and several small glass meeting booths/rooms with angled walls. On the floorplan, the best match is the large open office 504 KONTORSLANDSKAP next to the diagonal BALKONG edge, where several diamond/angled glass pods are drawn. The camera is most likely inside the upper-left of this open office, beside one of those glass pods and facing toward the windowed perimeter. | K29: =B29&"|"&C29 -> Floor 5|4.1 | M29: Floor 3|4.1 | N29: =IFERROR(__xludf.DUMMYFUNCTION("MIN(FILTER($I$2:$I109,$K$2:$K109=M29))"),17.804) -> 17.804 | O29: =IFERROR(__xludf.DUMMYFUNCTION("MAX(FILTER($I$2:$I109,$K$2:$K109=M29))"),19.105) -> 19.105 | P29: =O29-N29 -> 1.301
A30: T1.32 | B30: Floor 5 | C30: 4.1 | D30: Wide | E30: 42 | F30: 29 | G30: 35 | H30: 23 | I30: 9.22 | J30: The query shows a glass-partitioned open office area with many desks and exterior windows along angled facades, matching the large open workspace 504 KONTORSLANDSKAP. The camera appears to be near the small internal glass meeting pod/partition zone on the left side of that room, just southeast of passage 503 and looking toward the windowed perimeter. | K30: =B30&"|"&C30 -> Floor 5|4.1 | M30: Floor 3|4.2 | N30: =IFERROR(__xludf.DUMMYFUNCTION("MIN(FILTER($I$2:$I109,$K$2:$K109=M30))"),4.472) -> 4.472 | O30: =IFERROR(__xludf.DUMMYFUNCTION("MAX(FILTER($I$2:$I109,$K$2:$K109=M30))"),11.402) -> 11.402 | P30: =O30-N30 -> 6.93
A31: T1.33 | B31: Floor 5 | C31: 4.1 | D31: Wide | E31: 42 | F31: 29 | G31: 36 | H31: 21 | I31: 10 | J31: The query shows an open office area with perimeter windows and several small polygonal glass meeting rooms/booths. This best matches the central-right open office room 504 KONTORSLANDSKAP next to the diagonal balcony edge, where multiple diamond-shaped glass rooms are drawn. The camera appears to be just beside one of these glass rooms, near the upper-left part of 504, looking toward the exterior windows. | K31: =B31&"|"&C31 -> Floor 5|4.1 | M31: Floor 3|4.pano | N31: =IFERROR(__xludf.DUMMYFUNCTION("MIN(FILTER($I$2:$I109,$K$2:$K109=M31))"),15.556) -> 15.556 | O31: =IFERROR(__xludf.DUMMYFUNCTION("MAX(FILTER($I$2:$I109,$K$2:$K109=M31))"),19.849) -> 19.849 | P31: =O31-N31 -> 4.293
A32: T1.34 | B32: Floor 5 | C32: 4.2 | D32: Wide | E32: 42 | F32: 29 | G32: 31 | H32: 12 | I32: 20.248 | J32: The query shows a small glass-partitioned meeting room with a table and chairs, directly adjacent to an open office area and along the exterior window line. On the floorplan, the best match is room 506 (MÖTESRUM) at the top center-right, beside the open office 504. The camera appears to be positioned near the inner-left side of that meeting room, looking through the glass wall toward the open office. | K32: =B32&"|"&C32 -> Floor 5|4.2 | M32: Floor 3|5.1 | N32: =IFERROR(__xludf.DUMMYFUNCTION("MIN(FILTER($I$2:$I109,$K$2:$K109=M32))"),10.63) -> 10.63 | O32: =IFERROR(__xludf.DUMMYFUNCTION("MAX(FILTER($I$2:$I109,$K$2:$K109=M32))"),12.083) -> 12.083 | P32: =O32-N32 -> 1.453
A33: T1.35 | B33: Floor 5 | C33: 4.2 | D33: Wide | E33: 42 | F33: 29 | G33: 32 | H33: 12 | I33: 19.723 | J33: The query shows a small glazed meeting room with a table and chairs, immediately beside a larger open office area and along the exterior window facade. On the plan, room 506 (MÖTESRUM) best matches this: it is the meeting room at the top edge with windows on the exterior side and adjacent to the open office zone. The camera is most likely near the left/west end of room 506, looking through the glass wall toward the office area. | K33: =B33&"|"&C33 -> Floor 5|4.2 | M33: Floor 3|5.2 | N33: =IFERROR(__xludf.DUMMYFUNCTION("MIN(FILTER($I$2:$I109,$K$2:$K109=M33))"),3.606) -> 3.606 | O33: =IFERROR(__xludf.DUMMYFUNCTION("MAX(FILTER($I$2:$I109,$K$2:$K109=M33))"),8.246) -> 8.246 | P33: =O33-N33 -> 4.64
A34: T1.36 | B34: Floor 5 | C34: 4.2 | D34: Wide | E34: 42 | F34: 29 | G34: 32 | H34: 12 | I34: 19.723 | J34: The query shows a small glass-walled meeting room with a table and chairs, directly adjacent to a larger open office area and on the exterior window line. On the floorplan, room 506 MÖTESRUM best matches this setup: it is a meeting room along the top window façade and beside the large open office area 504. The point is placed inside 506 near its left/window side, matching the camera being inside the meeting room looking through glass toward the open office. | K34: =B34&"|"&C34 -> Floor 5|4.2 | M34: Floor 3|5.pano | N34: =IFERROR(__xludf.DUMMYFUNCTION("MIN(FILTER($I$2:$I109,$K$2:$K109=M34))"),6.403) -> 6.403 | O34: =IFERROR(__xludf.DUMMYFUNCTION("MAX(FILTER($I$2:$I109,$K$2:$K109=M34))"),12.806) -> 12.806 | P34: =O34-N34 -> 6.403
A35: T1.37 | B35: Floor 5 | C35: 4.pano | D35: Panorama | E35: 42 | F35: 29 | G35: 38 | H35: 17 | I35: 12.649 | J35: The query shows a small glass-walled meeting room beside the large open office, with exterior windows on one side and a glazed partition/door opening to the office on the other. This best matches room 506 (MÖTESRUM) at the top-center/right of the plan, adjacent to 504 KONTORSLANDSKAP. The camera appears to be placed inside that meeting room near its lower-left side, looking diagonally out toward the open office. | K35: =B35&"|"&C35 -> Floor 5|4.pano | M35: Floor 3|6.1 | N35: =IFERROR(__xludf.DUMMYFUNCTION("MIN(FILTER($I$2:$I109,$K$2:$K109=M35))"),9.487) -> 9.487 | O35: =IFERROR(__xludf.DUMMYFUNCTION("MAX(FILTER($I$2:$I109,$K$2:$K109=M35))"),10.77) -> 10.77 | P35: =O35-N35 -> 1.283
A36: T1.38 | B36: Floor 5 | C36: 4.pano | D36: Panorama | E36: 42 | F36: 29 | G36: 35 | H36: 12 | I36: 18.385 | J36: The query shows a small glass-walled meeting room with an oval table, directly adjacent to a larger open office area with many desks and extensive exterior windows along a slanted facade. This best matches room 506 (MÖTESRUM) next to the open office 504. The camera appears to be placed inside 506 near its right/east side, looking through the glass partition toward the open office and windows. | K36: =B36&"|"&C36 -> Floor 5|4.pano | M36: Floor 3|6.2 | N36: =IFERROR(__xludf.DUMMYFUNCTION("MIN(FILTER($I$2:$I109,$K$2:$K109=M36))"),9.487) -> 9.487 | O36: =IFERROR(__xludf.DUMMYFUNCTION("MAX(FILTER($I$2:$I109,$K$2:$K109=M36))"),10.77) -> 10.77 | P36: =O36-N36 -> 1.283
A37: T1.39 | B37: Floor 5 | C37: 4.pano | D37: Panorama | E37: 42 | F37: 29 | G37: 35 | H37: 12 | I37: 18.385 | J37: The query shows a small glass-walled meeting room with an oval table directly adjacent to a larger open office area along the windowed facade. On the plan, room 506 (MÖTESRUM) matches this: it is a meeting room beside the large open office 504/KONTORSLANDSKAP and along the angled exterior windows. The camera is most likely positioned inside room 506 near its lower-right side, looking through the glass toward the open office. | K37: =B37&"|"&C37 -> Floor 5|4.pano | M37: Floor 3|6_pano | N37: =IFERROR(__xludf.DUMMYFUNCTION("MIN(FILTER($I$2:$I109,$K$2:$K109=M37))"),8.944) -> 8.944 | O37: =IFERROR(__xludf.DUMMYFUNCTION("MAX(FILTER($I$2:$I109,$K$2:$K109=M37))"),11.18) -> 11.18 | P37: =O37-N37 -> 2.236
A38: T1.40 | B38: Floor 5 | C38: 5.1 | D38: Wide | E38: 46 | F38: 30 | G38: 30 | H38: 16 | I38: 21.26 | J38: The query shows a very small enclosed technical/storage-like room with two interior doors and double doors ahead; the wall sign appears to read KWC, which best matches the compact room 501 TEKNIKRUM near the stair/hiss core. The camera is likely positioned just inside this room facing toward the double doors, so I place it within room 501 near its upper-right side. | K38: =B38&"|"&C38 -> Floor 5|5.1
A39: T1.41 | B39: Floor 5 | C39: 5.1 | D39: Wide | E39: 46 | F39: 30 | G39: 30 | H39: 17 | I39: 20.616 | J39: The query shows a very small enclosed technical/electrical-style room with double doors ahead and another labeled door at right; on the plan the best match is room 501 TEKNIKRUM. The camera is likely just inside this room near its southeast side, looking roughly toward the north/northwest wall and doors. | K39: =B39&"|"&C39 -> Floor 5|5.1
A40: T1.42 | B40: Floor 5 | C40: 5.1 | D40: Wide | E40: 46 | F40: 30 | G40: 30 | H40: 17 | I40: 20.616 | J40: The query shows a very small service/technical room with double doors ahead and a wall label that appears to read KWC/RWC, matching the compact technical/service area 501 TEKNIKRUM near the stair core. The camera is likely inside that room, close to the doorway on the right side, facing the double doors/wall, so I place the point in the upper-right part of room 501. | K40: =B40&"|"&C40 -> Floor 5|5.1
...

Sheet Pixel prompt
A1: Id | B1: Floor | C1: Image id | D1: Image Type | E1: True x | F1: True y | G1: Predicted x | H1: Predicted y | I1: Euclidean error | J1: Reasoning | K1: Floor & Image id | L1: Column 2 | M1: Unique floor & image | N1: Column 4 | O1: Column 5 | P1: Notes | Q1: Column 17 | R1: Column 18 | S1: Column 19 | T1: Column 21 | U1: Column 1 | V1: Column 20
A2: T2.1 | B2: Floor 5 | C2: 1.1 | D2: Wide | E2: 39 | F2: 15 | G2: 36 | H2: 17 | I2: 3.606 | J2: The photo shows a kitchenette/pantry with microwaves, sink, fridge, and a sloped exterior wall with windows. On the floorplan, room 505 labeled 'PENTRY' matches this layout and sits beside the larger open office area seen through the doorway. The camera is most likely inside the pantry near its lower-left side, facing toward the doorway and sloped wall. | K2: =B2&"|"&C2 -> Floor 5|1.1 | M2: {=UNIQUE(K2:K109)} -> Floor 5|1.1 | N2: =IFERROR(__xludf.DUMMYFUNCTION("MIN(FILTER($I$2:$I109,$K$2:$K109=M2))"),2.828) -> 2.828 | O2: =IFERROR(__xludf.DUMMYFUNCTION("MAX(FILTER($I$2:$I109,$K$2:$K109=M2))"),3.606) -> 3.606 | P2: =O2-N2 -> 0.778 | R2: =COUNTIF(P2:P109,">0") -> 33 | S2: =COUNTIF(P2:P109,">0")/COUNTA(M2:M109) -> 0.91666667
A3: T2.2 | B3: Floor 5 | C3: 1.1 | D3: Wide | E3: 39 | F3: 15 | G3: 37 | H3: 17 | I3: 2.828 | J3: The photo shows a kitchenette/pantry with sloped ceiling and a doorway into an adjacent office area. On the floorplan, room 505 labeled 'PENTRY' matches this kitchenette and sits next to the open office area 504, consistent with the view through the door. The camera is most likely positioned inside the pantry near its lower-left side, looking toward the doorway. | K3: =B3&"|"&C3 -> Floor 5|1.1 | M3: Floor 5|1.2 | N3: =IFERROR(__xludf.DUMMYFUNCTION("MIN(FILTER($I$2:$I109,$K$2:$K109=M3))"),5.831) -> 5.831 | O3: =IFERROR(__xludf.DUMMYFUNCTION("MAX(FILTER($I$2:$I109,$K$2:$K109=M3))"),7.81) -> 7.81 | P3: =O3-N3 -> 1.979 | R3: =COUNTIF(P2:P109,">1") -> 18 | S3: =COUNTIF(P2:P109,">1")/COUNTA(M2:M109) -> 0.5
A4: T2.3 | B4: Floor 5 | C4: 1.1 | D4: Wide | E4: 39 | F4: 15 | G4: 37 | H4: 17 | I4: 2.828 | J4: The photo shows a kitchenette/pantry with cabinets, sink, microwaves, and a sloped roof. On the floorplan, room 505 is labeled PENTRY and sits beside the open office area, matching the visible doorway into offices and the angled exterior wall. The camera is most likely inside room 505 near its open side, facing the kitchenette wall and doorway. | K4: =B4&"|"&C4 -> Floor 5|1.1 | M4: Floor 5|1_pano | N4: =IFERROR(__xludf.DUMMYFUNCTION("MIN(FILTER($I$2:$I109,$K$2:$K109=M4))"),2.828) -> 2.828 | O4: =IFERROR(__xludf.DUMMYFUNCTION("MAX(FILTER($I$2:$I109,$K$2:$K109=M4))"),2.828) -> 2.828 | P4: =O4-N4 -> 0 | R4: =COUNTIF(P2:P109,">3") -> 7 | S4: =COUNTIF(P2:P109,">3")/COUNTA(M2:M109) -> 0.19444444
A5: T2.4 | B5: Floor 5 | C5: 1.2 | D5: Wide | E5: 39 | F5: 15 | G5: 36 | H5: 22 | I5: 7.616 | J5: The photo appears to be taken in the open office/kitchen transition area: tiled floor beside carpeted office space, with windows/open desks to the left and a kitchenette/fridge plus a small enclosed room/core area to the right. This best matches the central-right side of room 504 near the pantry/core boundary, just west of the 510/516/517 service cluster. | K5: =B5&"|"&C5 -> Floor 5|1.2 | M5: Floor 5|2.1 | N5: =IFERROR(__xludf.DUMMYFUNCTION("MIN(FILTER($I$2:$I109,$K$2:$K109=M5))"),1.0) -> 1 | O5: =IFERROR(__xludf.DUMMYFUNCTION("MAX(FILTER($I$2:$I109,$K$2:$K109=M5))"),4.472) -> 4.472 | P5: =O5-N5 -> 3.472 | R5: =COUNTIF(P2:P109,">5") -> 6 | S5: =COUNTIF(P2:P109,">5")/COUNTA(M2:M109) -> 0.16666667
A6: T2.5 | B6: Floor 5 | C6: 1.2 | D6: Wide | E6: 39 | F6: 15 | G6: 34 | H6: 21 | I6: 7.81 | J6: The photo appears to be taken in the open office/pantry transition area: carpeted open workspace with windows on the left, tiled kitchenette/pantry zone on the right, and a small partition wall between them. This best matches the boundary between room 505 PENTRY and 504 KONTORSLANDSKAP, near the passage toward 503. | K6: =B6&"|"&C6 -> Floor 5|1.2 | M6: Floor 5|2.2 | N6: =IFERROR(__xludf.DUMMYFUNCTION("MIN(FILTER($I$2:$I109,$K$2:$K109=M6))"),2.236) -> 2.236 | O6: =IFERROR(__xludf.DUMMYFUNCTION("MAX(FILTER($I$2:$I109,$K$2:$K109=M6))"),13.153) -> 13.153 | P6: =O6-N6 -> 10.917 | R6: =COUNTIF(P3:P109,">10") -> 3 | S6: =COUNTIF(P3:P109,">10")/COUNTA(M3:M109) -> 0.085714286
A7: T2.6 | B7: Floor 5 | C7: 1.2 | D7: Wide | E7: 39 | F7: 15 | G7: 36 | H7: 20 | I7: 5.831 | J7: The photo appears to be taken in the pantry/open-office transition area: tiled kitchenette floor on the right, carpeted office area with desks and windows on the left, and a small enclosed booth/door ahead. This best matches the boundary between room 505 PENRTY and 504 KONTORSLANDSKAP near the passage connection. | K7: =B7&"|"&C7 -> Floor 5|1.2 | M7: Floor 5|2.pano | N7: =IFERROR(__xludf.DUMMYFUNCTION("MIN(FILTER($I$2:$I109,$K$2:$K109=M7))"),1.0) -> 1 | O7: =IFERROR(__xludf.DUMMYFUNCTION("MAX(FILTER($I$2:$I109,$K$2:$K109=M7))"),3.162) -> 3.162 | P7: =O7-N7 -> 2.162
A8: T2.7 | B8: Floor 5 | C8: 1_pano | D8: Panorama | E8: 39 | F8: 15 | G8: 37 | H8: 17 | I8: 2.828 | J8: The photo shows a pantry/kitchenette opening into a larger meeting room with a sloped exterior wall and a row of low windows. This matches room 505 PANTRY adjoining 506 MÖTESRUM; the camera is best placed in the pantry near the kitchenette wall, looking into the meeting room and open office to the left. | K8: =B8&"|"&C8 -> Floor 5|1_pano | M8: Floor 5|3.1 | N8: =IFERROR(__xludf.DUMMYFUNCTION("MIN(FILTER($I$2:$I109,$K$2:$K109=M8))"),4.472) -> 4.472 | O8: =IFERROR(__xludf.DUMMYFUNCTION("MAX(FILTER($I$2:$I109,$K$2:$K109=M8))"),5.385) -> 5.385 | P8: =O8-N8 -> 0.913
A9: T2.8 | B9: Floor 5 | C9: 1_pano | D9: Panorama | E9: 39 | F9: 15 | G9: 37 | H9: 17 | I9: 2.828 | J9: The photo shows a pantry/kitchenette directly beside a low-sloped windowed meeting area, matching room 505 (PENTRY) opening into 506 (MÖTESRUM). The camera is best placed near the kitchenette side of 505, looking across into the meeting room with the row of low windows. | K9: =B9&"|"&C9 -> Floor 5|1_pano | M9: Floor 5|3.2 | N9: =IFERROR(__xludf.DUMMYFUNCTION("MIN(FILTER($I$2:$I109,$K$2:$K109=M9))"),4.0) -> 4 | O9: =IFERROR(__xludf.DUMMYFUNCTION("MAX(FILTER($I$2:$I109,$K$2:$K109=M9))"),5.099) -> 5.099 | P9: =O9-N9 -> 1.099
A10: T2.9 | B10: Floor 5 | C10: 1_pano | D10: Panorama | E10: 39 | F10: 15 | G10: 37 | H10: 17 | I10: 2.828 | J10: The photo shows a small pantry/kitchenette directly beside a sloped-roof meeting room with a row of low windows, matching room 505 (PENTRY) opening into 506 (MÖTESRUM). The camera is best placed near the boundary between these spaces, inside the pantry area looking across into the meeting room and open office. | K10: =B10&"|"&C10 -> Floor 5|1_pano | M10: Floor 5|3_pano | N10: =IFERROR(__xludf.DUMMYFUNCTION("MIN(FILTER($I$2:$I109,$K$2:$K109=M10))"),12.207) -> 12.207 | O10: =IFERROR(__xludf.DUMMYFUNCTION("MAX(FILTER($I$2:$I109,$K$2:$K109=M10))"),12.806) -> 12.806 | P10: =O10-N10 -> 0.599
A11: T2.10 | B11: Floor 5 | C11: 2.1 | D11: Wide | E11: 44 | F11: 16 | G11: 43 | H11: 16 | I11: 1 | J11: The photo shows a very small office under a sloped roof with two exterior windows meeting at an angled corner, which best matches the narrow corner office 507 at the top-right of the plan. The camera appears positioned inside that room, a bit back from the windows and looking toward the exterior corner. | K11: =B11&"|"&C11 -> Floor 5|2.1 | M11: Floor 5|4.1 | N11: =IFERROR(__xludf.DUMMYFUNCTION("MIN(FILTER($I$2:$I109,$K$2:$K109=M11))"),10.63) -> 10.63 | O11: =IFERROR(__xludf.DUMMYFUNCTION("MAX(FILTER($I$2:$I109,$K$2:$K109=M11))"),11.402) -> 11.402 | P11: =O11-N11 -> 0.772 | U11: utanför byggnad
A12: T2.11 | B12: Floor 5 | C12: 2.1 | D12: Wide | E12: 44 | F12: 16 | G12: 47 | H12: 17 | I12: 3.162 | J12: The photo shows a small attic-like office with strongly sloped ceilings and two exterior windows meeting at a corner. On the floorplan, the best match is the narrow corner office 507 at the angled façade, where two windowed exterior walls create this geometry. The camera is likely positioned slightly inside that room, looking toward the corner windows. | K12: =B12&"|"&C12 -> Floor 5|2.1 | M12: Floor 5|4.2 | N12: =IFERROR(__xludf.DUMMYFUNCTION("MIN(FILTER($I$2:$I109,$K$2:$K109=M12))"),19.723) -> 19.723 | O12: =IFERROR(__xludf.DUMMYFUNCTION("MAX(FILTER($I$2:$I109,$K$2:$K109=M12))"),20.591) -> 20.591 | P12: =O12-N12 -> 0.868
A13: T2.12 | B13: Floor 5 | C13: 2.1 | D13: Wide | E13: 44 | F13: 16 | G13: 42 | H13: 20 | I13: 4.472 | J13: The query shows a very small attic-like office with a strongly sloped ceiling and two exterior windows meeting at a corner, which best matches the narrow corner office 507 on the angled outer facade. The camera appears to be inside that room near its interior side, aimed toward the exterior corner windows. | K13: =B13&"|"&C13 -> Floor 5|2.1 | M13: Floor 5|4.pano | N13: =IFERROR(__xludf.DUMMYFUNCTION("MIN(FILTER($I$2:$I109,$K$2:$K109=M13))"),19.235) -> 19.235 | O13: =IFERROR(__xludf.DUMMYFUNCTION("MAX(FILTER($I$2:$I109,$K$2:$K109=M13))"),19.723) -> 19.723 | P13: =O13-N13 -> 0.488
A14: T2.13 | B14: Floor 5 | C14: 2.2 | D14: Wide | E14: 44 | F14: 16 | G14: 42 | H14: 28 | I14: 12.166 | J14: The photo appears to be taken inside a small enclosed office with carpet, looking through a single door into the larger open office area that has visible columns. On the floorplan, room 517 (KONTOR) best matches this setup: a small office opening directly into the open office landscape near the columns and circulation area. | K14: =B14&"|"&C14 -> Floor 5|2.2 | M14: Floor 5|5.1 | N14: =IFERROR(__xludf.DUMMYFUNCTION("MIN(FILTER($I$2:$I109,$K$2:$K109=M14))"),19.416) -> 19.416 | O14: =IFERROR(__xludf.DUMMYFUNCTION("MAX(FILTER($I$2:$I109,$K$2:$K109=M14))"),21.401) -> 21.401 | P14: =O14-N14 -> 1.985
A15: T2.14 | B15: Floor 5 | C15: 2.2 | D15: Wide | E15: 44 | F15: 16 | G15: 42 | H15: 29 | I15: 13.153 | J15: The photo appears taken inside a small office looking out through a single doorway into the larger open office area with visible round columns. On the plan, the small enclosed offices along the right side (especially room 517) border the open office landscape and match this setup best. The point is placed inside room 517 near its doorway facing the open area. | K15: =B15&"|"&C15 -> Floor 5|2.2 | M15: Floor 5|5.2 | N15: =IFERROR(__xludf.DUMMYFUNCTION("MIN(FILTER($I$2:$I109,$K$2:$K109=M15))"),1.0) -> 1 | O15: =IFERROR(__xludf.DUMMYFUNCTION("MAX(FILTER($I$2:$I109,$K$2:$K109=M15))"),1.0) -> 1 | P15: =O15-N15 -> 0 | U15: väldigt annorlunda svar från de tidigare två
A16: T2.15 | B16: Floor 5 | C16: 2.2 | D16: Wide | E16: 44 | F16: 16 | G16: 42 | H16: 17 | I16: 2.236 | J16: The photo appears to be taken inside a small office looking out through a single door into the larger open office area with visible columns. On the plan, the small perimeter offices along the right side (especially room 507) open into the large room 504 and best match this setup. The camera is placed inside that office near the outer wall, facing inward toward the doorway and open office. | K16: =B16&"|"&C16 -> Floor 5|2.2 | M16: Floor 5|5.pano | N16: =IFERROR(__xludf.DUMMYFUNCTION("MIN(FILTER($I$2:$I109,$K$2:$K109=M16))"),2.0) -> 2 | O16: =IFERROR(__xludf.DUMMYFUNCTION("MAX(FILTER($I$2:$I109,$K$2:$K109=M16))"),3.606) -> 3.606 | P16: =O16-N16 -> 1.606
A17: T2.16 | B17: Floor 5 | C17: 2.pano | D17: Panorama | E17: 44 | F17: 16 | G17: 43 | H17: 19 | I17: 3.162 | J17: The photo appears to be taken inside a small perimeter office with a sloped exterior wall and multiple windows on the right, looking back through the door into the corridor. On the floorplan, room 507 best matches this shape and window placement along the angled façade, so the camera is placed inside 507 near the window side facing the doorway. | K17: =B17&"|"&C17 -> Floor 5|2.pano | M17: Floor 5|6.1 | N17: =IFERROR(__xludf.DUMMYFUNCTION("MIN(FILTER($I$2:$I109,$K$2:$K109=M17))"),5.831) -> 5.831 | O17: =IFERROR(__xludf.DUMMYFUNCTION("MAX(FILTER($I$2:$I109,$K$2:$K109=M17))"),6.403) -> 6.403 | P17: =O17-N17 -> 0.572
A18: T2.17 | B18: Floor 5 | C18: 2.pano | D18: Panorama | E18: 44 | F18: 16 | G18: 45 | H18: 16 | I18: 1 | J18: The photo appears to be from a small perimeter office with a sloped exterior wall/ceiling, windows along the right side, and a single inward door opening to the corridor. On the floorplan, room 507 best matches this wedge-shaped office at the top-right edge; the camera seems positioned inside that room near the windowed exterior wall, facing back toward the door. | K18: =B18&"|"&C18 -> Floor 5|2.pano | M18: Floor 5|6.2 | N18: =IFERROR(__xludf.DUMMYFUNCTION("MIN(FILTER($I$2:$I109,$K$2:$K109=M18))"),3.606) -> 3.606 | O18: =IFERROR(__xludf.DUMMYFUNCTION("MAX(FILTER($I$2:$I109,$K$2:$K109=M18))"),5.657) -> 5.657 | P18: =O18-N18 -> 2.051
A19: T2.18 | B19: Floor 5 | C19: 2.pano | D19: Panorama | E19: 44 | F19: 16 | G19: 43 | H19: 19 | I19: 3.162 | J19: The query shows a small attic-like office with strongly sloped ceiling, exterior windows along the right side, and a door opening toward a corridor. On the plan, the most likely match is one of the narrow perimeter offices on the angled right facade; room 507 best fits the small size, exterior window wall, and doorway into the internal circulation zone. The point is placed inside room 507, slightly in from the window side, representing the camera position facing the door. | K19: =B19&"|"&C19 -> Floor 5|2.pano | M19: Floor 5|6_pano | N19: =IFERROR(__xludf.DUMMYFUNCTION("MIN(FILTER($I$2:$I109,$K$2:$K109=M19))"),5.0) -> 5 | O19: =IFERROR(__xludf.DUMMYFUNCTION("MAX(FILTER($I$2:$I109,$K$2:$K109=M19))"),7.211) -> 7.211 | P19: =O19-N19 -> 2.211
A20: T2.19 | B20: Floor 5 | C20: 3.1 | D20: Wide | E20: 39 | F20: 22 | G20: 43 | H20: 20 | I20: 4.472 | J20: The photo shows a small perimeter office with several desks directly along an exterior window wall and a corner-like glazed facade. On the plan, room 508 (Kontor) best matches this size, shape, and long exterior window exposure on the right side of the building. The camera is likely positioned inside that room, a bit back from the windows and looking outward toward the facade. | K20: =B20&"|"&C20 -> Floor 5|3.1 | M20: Floor 3|1.1 | N20: =IFERROR(__xludf.DUMMYFUNCTION("MIN(FILTER($I$2:$I109,$K$2:$K109=M20))"),30.414) -> 30.414 | O20: =IFERROR(__xludf.DUMMYFUNCTION("MAX(FILTER($I$2:$I109,$K$2:$K109=M20))"),31.145) -> 31.145 | P20: =O20-N20 -> 0.731
A21: T2.20 | B21: Floor 5 | C21: 3.1 | D21: Wide | E21: 39 | F21: 22 | G21: 44 | H21: 20 | I21: 5.385 | J21: The query shows a small office with several desks directly against a long exterior window facade and a corner view outside. On the floorplan, the best match is the window-lined office 508 KONTOR along the angled right exterior wall, near its upper corner where two exterior-facing window directions meet. | K21: =B21&"|"&C21 -> Floor 5|3.1 | M21: Floor 3|1.2 | N21: =IFERROR(__xludf.DUMMYFUNCTION("MIN(FILTER($I$2:$I109,$K$2:$K109=M21))"),12.53) -> 12.53 | O21: =IFERROR(__xludf.DUMMYFUNCTION("MAX(FILTER($I$2:$I109,$K$2:$K109=M21))"),28.16) -> 28.16 | P21: =O21-N21 -> 15.63
A22: T2.21 | B22: Floor 5 | C22: 3.1 | D22: Wide | E22: 39 | F22: 22 | G22: 43 | H22: 20 | I22: 4.472 | J22: The photo shows an office with multiple desks directly along an exterior window facade and a corner-like glazed edge. On the floorplan, the best match is the small perimeter office 507 (KONTOR) on the angled northeast facade, which has windows on two exterior sides and fits the compact furnished office appearance. The camera is placed slightly inside that room, looking out toward the windows. | K22: =B22&"|"&C22 -> Floor 5|3.1 | M22: Floor 3|1.pano | N22: =IFERROR(__xludf.DUMMYFUNCTION("MIN(FILTER($I$2:$I109,$K$2:$K109=M22))"),25.71) -> 25.71 | O22: =IFERROR(__xludf.DUMMYFUNCTION("MAX(FILTER($I$2:$I109,$K$2:$K109=M22))"),31.575) -> 31.575 | P22: =O22-N22 -> 5.865
A23: T2.22 | B23: Floor 5 | C23: 3.2 | D23: Wide | E23: 39 | F23: 22 | G23: 34 | H23: 23 | I23: 5.099 | J23: The photo shows an open office/lounge area with tables, many windows along the outer wall, and a freestanding partition with a TV. This best matches room 504 KONTORSLANDSKAP near the slanted balcony edge and adjacent open workspace, with the camera positioned just inside the open area looking toward an internal partition and the windowed perimeter. | K23: =B23&"|"&C23 -> Floor 5|3.2 | M23: Floor 3|2.1 | N23: =IFERROR(__xludf.DUMMYFUNCTION("MIN(FILTER($I$2:$I109,$K$2:$K109=M23))"),3.0) -> 3 | O23: =IFERROR(__xludf.DUMMYFUNCTION("MAX(FILTER($I$2:$I109,$K$2:$K109=M23))"),3.606) -> 3.606 | P23: =O23-N23 -> 0.606
A24: T2.23 | B24: Floor 5 | C24: 3.2 | D24: Wide | E24: 39 | F24: 22 | G24: 35 | H24: 23 | I24: 4.123 | J24: The photo shows an open office/lounge area with meeting tables, low windows along the exterior wall, and a central partition with a TV. This best matches room 504 KONTORSLANDSKAP near the balcony edge and windowed side, with the camera positioned slightly left of center in the open area looking toward an internal partition and the exterior windows. | K24: =B24&"|"&C24 -> Floor 5|3.2 | M24: Floor 3|2.2 | N24: =IFERROR(__xludf.DUMMYFUNCTION("MIN(FILTER($I$2:$I109,$K$2:$K109=M24))"),4.123) -> 4.123 | O24: =IFERROR(__xludf.DUMMYFUNCTION("MAX(FILTER($I$2:$I109,$K$2:$K109=M24))"),5.099) -> 5.099 | P24: =O24-N24 -> 0.976
A25: T2.24 | B25: Floor 5 | C25: 3.2 | D25: Wide | E25: 39 | F25: 22 | G25: 35 | H25: 22 | I25: 4 | J25: The photo shows an open office/lounge area with meeting tables by a long exterior window wall and a small partition wall carrying a TV. This best matches the large open room 504 (KONTORSLANDSKAP) near the balcony edge, looking toward the windows on the right/northeast side. The camera appears to be inside the open area just southwest of the partition/TV wall. | K25: =B25&"|"&C25 -> Floor 5|3.2 | M25: Floor 3|2_pano | N25: =IFERROR(__xludf.DUMMYFUNCTION("MIN(FILTER($I$2:$I109,$K$2:$K109=M25))"),4.123) -> 4.123 | O25: =IFERROR(__xludf.DUMMYFUNCTION("MAX(FILTER($I$2:$I109,$K$2:$K109=M25))"),6.403) -> 6.403 | P25: =O25-N25 -> 2.28
A26: T2.25 | B26: Floor 5 | C26: 3_pano | D26: Panorama | E26: 39 | F26: 22 | G26: 32 | H26: 12 | I26: 12.207 | J26: The query shows a meeting room with a large table, exterior windows along one side, and adjacent glass-partitioned offices/corridor on the other. This best matches room 506 MÖTESRUM at the top-center of the plan, with the camera positioned inside the room near its lower side looking toward the windows and nearby office area. | K26: =B26&"|"&C26 -> Floor 5|3_pano | M26: Floor 3|3.1 | N26: =IFERROR(__xludf.DUMMYFUNCTION("MIN(FILTER($I$2:$I109,$K$2:$K109=M26))"),2.828) -> 2.828 | O26: =IFERROR(__xludf.DUMMYFUNCTION("MAX(FILTER($I$2:$I109,$K$2:$K109=M26))"),5.385) -> 5.385 | P26: =O26-N26 -> 2.557
A27: T2.26 | B27: Floor 5 | C27: 3_pano | D27: Panorama | E27: 39 | F27: 22 | G27: 32 | H27: 12 | I27: 12.207 | J27: The query shows a meeting room with a large conference table, windows along one exterior side, and glass-walled offices/corridor on the opposite side. On the floorplan, room 506 (MÖTESRUM) best matches this layout, with the camera likely positioned inside that room near its lower-central area facing toward the glass partitions and adjacent offices. | K27: =B27&"|"&C27 -> Floor 5|3_pano | M27: Floor 3|3.2 | N27: =IFERROR(__xludf.DUMMYFUNCTION("MIN(FILTER($I$2:$I109,$K$2:$K109=M27))"),5.385) -> 5.385 | O27: =IFERROR(__xludf.DUMMYFUNCTION("MAX(FILTER($I$2:$I109,$K$2:$K109=M27))"),6.083) -> 6.083 | P27: =O27-N27 -> 0.698
A28: T2.27 | B28: Floor 5 | C28: 3_pano | D28: Panorama | E28: 39 | F28: 22 | G28: 31 | H28: 12 | I28: 12.806 | J28: The query shows a large meeting room with a conference table, windows along the exterior wall on one side, and interior glass offices/corridor on the opposite side. This best matches room 506 MÖTESRUM at the top-center/right of the plan. The camera appears placed inside that room near its lower-left/central area, looking across the room toward the glass-partition side and windows. | K28: =B28&"|"&C28 -> Floor 5|3_pano | M28: Floor 3|3_pano | N28: =IFERROR(__xludf.DUMMYFUNCTION("MIN(FILTER($I$2:$I109,$K$2:$K109=M28))"),6.708) -> 6.708 | O28: =IFERROR(__xludf.DUMMYFUNCTION("MAX(FILTER($I$2:$I109,$K$2:$K109=M28))"),8.544) -> 8.544 | P28: =O28-N28 -> 1.836
A29: T2.31 | B29: Floor 5 | C29: 4.1 | D29: Wide | E29: 42 | F29: 29 | G29: 33 | H29: 22 | I29: 11.402 | J29: The photo shows a small glass-walled meeting room with angled glass partitions opening directly into the large open office by the window façade. On the plan, room 506 (MÖTESRUM) has this distinctive angled shape and sits adjacent to the open office area 504 along the exterior windows, matching the view and geometry. The camera is most likely inside 506 near its lower-right side, looking out through the glass door toward the open office. | K29: =B29&"|"&C29 -> Floor 5|4.1 | M29: Floor 3|4.1 | N29: =IFERROR(__xludf.DUMMYFUNCTION("MIN(FILTER($I$2:$I109,$K$2:$K109=M29))"),17.692) -> 17.692 | O29: =IFERROR(__xludf.DUMMYFUNCTION("MAX(FILTER($I$2:$I109,$K$2:$K109=M29))"),18.385) -> 18.385 | P29: =O29-N29 -> 0.693
A30: T2.32 | B30: Floor 5 | C30: 4.1 | D30: Wide | E30: 42 | F30: 29 | G30: 35 | H30: 21 | I30: 10.63 | J30: The photo appears to be taken inside a small glass-walled meeting room looking out into the large open office by the window façade. On the plan, room 506 (MÖTESRUM) matches this: it is a meeting room opening into the large 504 office landscape, with exterior windows on two angled sides consistent with the view. The camera is likely near the lower-left/inner side of room 506, aimed outward through the glass partition and door. | K30: =B30&"|"&C30 -> Floor 5|4.1 | M30: Floor 3|4.2 | N30: =IFERROR(__xludf.DUMMYFUNCTION("MIN(FILTER($I$2:$I109,$K$2:$K109=M30))"),3.162) -> 3.162 | O30: =IFERROR(__xludf.DUMMYFUNCTION("MAX(FILTER($I$2:$I109,$K$2:$K109=M30))"),3.606) -> 3.606 | P30: =O30-N30 -> 0.444 | U30: säger att den är i 506 (fel) men placerar inte positionen i 506 ändå
A31: T2.33 | B31: Floor 5 | C31: 4.1 | D31: Wide | E31: 42 | F31: 29 | G31: 35 | H31: 20 | I31: 11.402 | J31: The photo appears to be taken inside the small glazed meeting room 506 (MÖTESRUM), looking out through its glass partitions into the adjacent open office area 504. The angular glass walls and nearby open office with exterior windows match the top-central meeting room position, so the camera is best placed slightly inside room 506 near its southeast glass edge. | K31: =B31&"|"&C31 -> Floor 5|4.1 | M31: Floor 3|4.pano | N31: =IFERROR(__xludf.DUMMYFUNCTION("MIN(FILTER($I$2:$I109,$K$2:$K109=M31))"),16.279) -> 16.279 | O31: =IFERROR(__xludf.DUMMYFUNCTION("MAX(FILTER($I$2:$I109,$K$2:$K109=M31))"),18.385) -> 18.385 | P31: =O31-N31 -> 2.106
A32: T2.34 | B32: Floor 5 | C32: 4.2 | D32: Wide | E32: 42 | F32: 29 | G32: 32 | H32: 11 | I32: 20.591 | J32: The photo appears to be taken inside a small glass-walled meeting room along the exterior facade: there is a conference table, chairs, full-height glazing to an adjacent open office, and windows directly to the outside. On the floorplan, room 506 (MÖTESRUM) best matches this setup, positioned on the outer windowed edge and adjacent to the open office area. The camera seems placed near the inner side of that room, looking along the glass partition toward the open office. | K32: =B32&"|"&C32 -> Floor 5|4.2 | M32: Floor 3|5.1 | N32: =IFERROR(__xludf.DUMMYFUNCTION("MIN(FILTER($I$2:$I109,$K$2:$K109=M32))"),11.314) -> 11.314 | O32: =IFERROR(__xludf.DUMMYFUNCTION("MAX(FILTER($I$2:$I109,$K$2:$K109=M32))"),18.385) -> 18.385 | P32: =O32-N32 -> 7.071
A33: T2.35 | B33: Floor 5 | C33: 4.2 | D33: Wide | E33: 42 | F33: 29 | G33: 32 | H33: 12 | I33: 19.723 | J33: The photo appears to be taken inside the meeting room labeled 506 MÖTESRUM: it has a conference table and chairs, exterior windows along one side, and a glass wall looking into the open office area with desks on the other side. The camera seems positioned near the inner-left side of that room, facing along the windowed wall toward the glass partition. | K33: =B33&"|"&C33 -> Floor 5|4.2 | M33: Floor 3|5.2 | N33: =IFERROR(__xludf.DUMMYFUNCTION("MIN(FILTER($I$2:$I109,$K$2:$K109=M33))"),2.0) -> 2 | O33: =IFERROR(__xludf.DUMMYFUNCTION("MAX(FILTER($I$2:$I109,$K$2:$K109=M33))"),8.062) -> 8.062 | P33: =O33-N33 -> 6.062
A34: T2.36 | B34: Floor 5 | C34: 4.2 | D34: Wide | E34: 42 | F34: 29 | G34: 32 | H34: 12 | I34: 19.723 | J34: The photo appears to be taken inside the large meeting room 506 MÖTESRUM: it has a conference table/chairs, exterior windows along one side, and a glass partition looking into the open office area (504) on the other side. The camera seems positioned near the left/west end of room 506, close to the window wall and facing along the glass wall toward the office. | K34: =B34&"|"&C34 -> Floor 5|4.2 | M34: Floor 3|5.pano | N34: =IFERROR(__xludf.DUMMYFUNCTION("MIN(FILTER($I$2:$I109,$K$2:$K109=M34))"),2.236) -> 2.236 | O34: =IFERROR(__xludf.DUMMYFUNCTION("MAX(FILTER($I$2:$I109,$K$2:$K109=M34))"),16.031) -> 16.031 | P34: =O34-N34 -> 13.795
A35: T2.37 | B35: Floor 5 | C35: 4.pano | D35: Panorama | E35: 42 | F35: 29 | G35: 33 | H35: 12 | I35: 19.235 | J35: The photo shows a small glass-walled meeting room with an oval table directly adjacent to a larger open office area and perimeter windows. On the floorplan, room 506 (MÖTESRUM) matches this layout: a meeting room along the outer windowed facade, next to the open office area 504 through angled glass partitions. The estimated camera position is inside 506 near its right/east side, looking across the glass toward the open office. | K35: =B35&"|"&C35 -> Floor 5|4.pano | M35: Floor 3|6.1 | N35: =IFERROR(__xludf.DUMMYFUNCTION("MIN(FILTER($I$2:$I109,$K$2:$K109=M35))"),9.22) -> 9.22 | O35: =IFERROR(__xludf.DUMMYFUNCTION("MAX(FILTER($I$2:$I109,$K$2:$K109=M35))"),9.849) -> 9.849 | P35: =O35-N35 -> 0.629
A36: T2.38 | B36: Floor 5 | C36: 4.pano | D36: Panorama | E36: 42 | F36: 29 | G36: 32 | H36: 12 | I36: 19.723 | J36: The query shows a small glass-walled meeting room with an oval table directly adjacent to a large open office area and along an exterior window facade. On the floorplan, room 506 (MÖTESRUM) matches this: it is a meeting room on the outer windowed edge, next to the open office area 504 and separated by angled glass walls near the central core. The point is placed inside 506 near its glass boundary toward the open office. | K36: =B36&"|"&C36 -> Floor 5|4.pano | M36: Floor 3|6.2 | N36: =IFERROR(__xludf.DUMMYFUNCTION("MIN(FILTER($I$2:$I109,$K$2:$K109=M36))"),10.296) -> 10.296 | O36: =IFERROR(__xludf.DUMMYFUNCTION("MAX(FILTER($I$2:$I109,$K$2:$K109=M36))"),10.296) -> 10.296 | P36: =O36-N36 -> 0
A37: T2.39 | B37: Floor 5 | C37: 4.pano | D37: Panorama | E37: 42 | F37: 29 | G37: 32 | H37: 12 | I37: 19.723 | J37: The photo appears to be taken inside a small glass-walled meeting room with a curved/angled glass partition, directly adjacent to the open office area and perimeter windows. On the floorplan, room 506 (MÖTESRUM) best matches this enclosed meeting room at the top-center, next to the open office/atrium side, so the camera is placed inside that room near its inner side facing outward. | K37: =B37&"|"&C37 -> Floor 5|4.pano | M37: Floor 3|6_pano | N37: =IFERROR(__xludf.DUMMYFUNCTION("MIN(FILTER($I$2:$I109,$K$2:$K109=M37))"),9.487) -> 9.487 | O37: =IFERROR(__xludf.DUMMYFUNCTION("MAX(FILTER($I$2:$I109,$K$2:$K109=M37))"),10.296) -> 10.296 | P37: =O37-N37 -> 0.809
A38: T2.40 | B38: Floor 5 | C38: 5.1 | D38: Wide | E38: 46 | F38: 30 | G38: 30 | H38: 17 | I38: 20.616 | J38: The photo shows a very small enclosed technical/storage-like room with double doors ahead and another door to the side, matching the compact room 501 TEKNIKRUM next to the stair/hiss core. The camera appears to be inside that room facing the wall/doors near its upper-left side. | K38: =B38&"|"&C38 -> Floor 5|5.1 | U38: förklarar rätt plats men positioner helt fel
A39: T2.41 | B39: Floor 5 | C39: 5.1 | D39: Wide | E39: 46 | F39: 30 | G39: 30 | H39: 19 | I39: 19.416 | J39: The photo shows a very small vestibule/storage-like room with double doors ahead and a side door labeled “RWC,” which matches the tiny room 516 ELC next to room 515 RWC in the lower-right service core. The camera is likely standing inside 516 looking toward its double-door wall. | K39: =B39&"|"&C39 -> Floor 5|5.1 | U39: förklarar rätt plats men positioner helt fel
A40: T2.42 | B40: Floor 5 | C40: 5.1 | D40: Wide | E40: 46 | F40: 30 | G40: 29 | H40: 17 | I40: 21.401 | J40: The photo appears to be taken inside a very small vestibule/storage-like room with double doors ahead and a side door labeled 'RWC', which matches the compact restroom-related area around room 515 (RWC) and the adjacent small lobby/corridor near rooms 514–516. The camera is likely positioned just inside that small nook, facing inward toward the doors. | K40: =B40&"|"&C40 -> Floor 5|5.1
...

Sheet Semantic prompt
A1: Id | B1: Floor | C1: Image id | D1: Image Type | E1: True x | F1: True y | G1: Predicted x | H1: Predicted y | I1: Euclidean error | J1: Reasoning | K1: Floor & Image id | M1: Unique floor & image | N1: Max EE | O1: Min EE | P1: Diff between max and min | Q1: Column 5 | R1: No of changed groups | S1: Percentage of changed groups | T1: Notes
